<?xml version="1.0" ?>
<robot name="wali">

  <link name="base_link">
    <visual>
      <origin xyz="0 0 0" rpy="0 0 0"/>
      <geometry>
        <box size="0.21 0.17 0.09"/>
      </geometry>
      <material name="gray">
        <color rgba="1 0.4 0 1"/>
      </material>
    </visual>
    <inertial>
      <mass value="2"/>
      <origin xyz="0 0 0.0"/>
      <inertia ixx="0.01" ixy="0.0" ixz="0.0" iyy="0.01" iyz="0.0" izz="0.5"/>
    </inertial>
    <collision>
      <origin xyz="0 0 0" rpy="0 0 0"/>
      <geometry>
        <box size="0.3 0.25 0.5"/>
      </geometry>
    </collision>
  </link>
  <gazebo reference="base_link">
    <material>Gazebo/Red</material>
  </gazebo>
  <gazebo reference="usb_camera">
    <material>Gazebo/Black</material>
  </gazebo>
  <link name="usb_camera">
    <inertial>
      <mass value="0.1"/>
      <origin xyz="0 0 0"/>
      <inertia ixx="0.01" ixy="0.0" ixz="0.0" iyy="0.01" iyz="0.0" izz="0.01"/>
    </inertial>
    <visual>
      <origin xyz="0 0 0" rpy="0 0 0"/>
      <geometry>
          <box size="0.01 0.04 0.04"/>
      </geometry>
      <material name="black"/>
    </visual>
    <collision>
      <origin xyz="0.0 0.0 0.0" rpy="0 0 0"/>
      <geometry>
          <box size="0.01 0.04 0.04"/>
      </geometry>
    </collision>
  </link>
  <joint name="camera_base_link_joint" type="fixed">
    <origin xyz="0.07 0 0.05" rpy="0 0 0"/>
    <parent link="base_link"/>
    <child link="usb_camera"/>
    <axis xyz="0 1 0"/>
  </joint>
  <gazebo reference="laser_link">
    <material>Gazebo/Black</material>
  </gazebo>
  <link name="laser_link">
		<visual>
			<origin xyz=" 0 0 0 " rpy="0 0 0" />
			<geometry>
				<cylinder length="0.05" radius="0.05"/>
			</geometry>
			<material name="black"/>
		</visual>
    <inertial>
      <mass value="2"/>
      <origin xyz="0 0 0.0"/>
      <inertia ixx="0.01" ixy="0.0" ixz="0.0" iyy="0.01" iyz="0.0" izz="0.5"/>
    </inertial>
  </link>
  <joint name="laser_joint" type="fixed">
    <origin xyz="0 0 0.05" rpy="0 0 0"/>
    <parent link="base_link"/>
    <child link="laser_link"/>
  </joint>
  <joint name="left_front_motor_joint" type="fixed">
    <origin xyz="-0.07 0.09 -0.02" rpy="0 0 0"/>
    <parent link="base_link"/>
    <child link="left_front_motor"/>
    <axis xyz="0 1 0"/>
  </joint>
  <gazebo reference="left_front_motor">
    <material>Gazebo/Yellow</material>
  </gazebo>
  <link name="left_front_motor">
    <visual>
      <origin xyz="0 0 0" rpy="1.5707 0 0"/>
      <geometry>
        <cylinder radius="0.02" length="0.08"/>
      </geometry>
      <material name="yellow">
        <color rgba="0.75 0.75 0.75 1"/>
      </material>
    </visual>
    <inertial>
      <mass value="2"/>
      <origin xyz="0 0 0.0"/>
      <inertia ixx="0.01" ixy="0.0" ixz="0.0" iyy="0.01" iyz="0.0" izz="0.5"/>
    </inertial>
  </link>
  <joint name="left_front_wheel_joint" type="continuous">
    <origin xyz="0 0.05 0" rpy="0 0 0"/>
    <parent link="left_front_motor"/>
    <child link="left_front_wheel"/>
    <axis xyz="0 1 0"/>
  </joint>
  <gazebo reference="left_front_wheel">
    <material>Gazebo/Black</material>
  </gazebo>
  <link name="left_front_wheel">
    <visual>
      <origin xyz="0 0 0" rpy="1.5707 1.5707 0"/>
      <geometry>
        <cylinder radius="0.04" length="0.04"/>
      </geometry>
      <material name="black">
        <color rgba="0.75 0.75 0.75 1"/>
      </material>
    </visual>
    <inertial>
      <mass value="2"/>
      <origin xyz="0 0 0.0"/>
      <inertia ixx="0.01" ixy="0.0" ixz="0.0" iyy="0.01" iyz="0.0" izz="0.5"/>
    </inertial>
  </link>
  <joint name="left_back_motor_joint" type="fixed">
    <origin xyz="-0.07 -0.09 -0.02" rpy="0 0 0"/>
    <parent link="base_link"/>
    <child link="left_back_motor"/>
    <axis xyz="0 1 0"/>
  </joint>
  <gazebo reference="left_back_motor">
    <material>Gazebo/Yellow</material>
  </gazebo>
  <link name="left_back_motor">
    <visual>
      <origin xyz="0 0 0" rpy="1.5707 0 0"/>
      <geometry>
        <cylinder radius="0.02" length="0.08"/>
      </geometry>
      <material name="yellow">
        <color rgba="0.75 0.75 0.75 1"/>
      </material>
    </visual>
    <inertial>
      <mass value="2"/>
      <origin xyz="0 0 0.0"/>
      <inertia ixx="0.01" ixy="0.0" ixz="0.0" iyy="0.01" iyz="0.0" izz="0.5"/>
    </inertial>
  </link>

  <joint name="left_back_wheel_joint" type="continuous">
    <origin xyz="0 -0.05 0" rpy="0 0 0"/>
    <parent link="left_back_motor"/>
    <child link="left_back_wheel"/>
    <axis xyz="0 1 0"/>
  </joint>
  <gazebo reference="left_back_wheel">
    <material>Gazebo/Black</material>
  </gazebo>

  <link name="left_back_wheel">
    <visual>
      <origin xyz="0 0 0" rpy="1.5707 1.5707 0"/>
      <geometry>
        <cylinder radius="0.04" length="0.04"/>
      </geometry>
      <material name="black">
        <color rgba="0.75 0.75 0.75 1"/>
      </material>
    </visual>
    <inertial>
      <mass value="2"/>
      <origin xyz="0 0 0.0"/>
      <inertia ixx="0.01" ixy="0.0" ixz="0.0" iyy="0.01" iyz="0.0" izz="0.5"/>
    </inertial>
  </link>
  <joint name="right_front_motor_joint" type="fixed">
    <origin xyz="0.07 0.09 -0.02" rpy="0 0 0"/>
    <parent link="base_link"/>
    <child link="right_front_motor"/>
    <axis xyz="0 1 0"/>
  </joint>
  <gazebo reference="right_front_motor">
    <material>Gazebo/Yellow</material>
  </gazebo>


  <link name="right_front_motor">
    <visual>
      <origin xyz="0 0 0" rpy="1.5707 0 0"/>
      <geometry>
        <cylinder radius="0.02" length="0.08"/>
      </geometry>
      <material name="yellow">
        <color rgba="0.75 0.75 0.75 1"/>
      </material>
    </visual>
    <inertial>
      <mass value="2"/>
      <origin xyz="0 0 0.0"/>
      <inertia ixx="0.01" ixy="0.0" ixz="0.0" iyy="0.01" iyz="0.0" izz="0.5"/>
    </inertial>
  </link>
  <joint name="right_front_wheel_joint" type="continuous">
    <origin xyz="0 -0.05 0" rpy="0 0 0"/>
    <parent link="right_front_motor"/>
    <child link="right_front_wheel"/>
    <axis xyz="0 1 0"/>
  </joint>
  <gazebo reference="right_front_wheel">
    <material>Gazebo/Black</material>
  </gazebo>
  <link name="right_front_wheel">
    <visual>
      <origin xyz="0 0.1 0" rpy="1.5707 1.5707 0"/>
      <geometry>
        <cylinder radius="0.04" length="0.04"/>
      </geometry>
      <material name="black">
        <color rgba="0.75 0.75 0.75 1"/>
      </material>
    </visual>
    <inertial>
      <mass value="2"/>
      <origin xyz="0 0 0.0"/>
      <inertia ixx="0.01" ixy="0.0" ixz="0.0" iyy="0.01" iyz="0.0" izz="0.5"/>
    </inertial>
  </link>
  
  <joint name="right_back_motor_joint" type="fixed">
    <origin xyz="0.07 -0.09 -0.02" rpy="0 0 0"/>
    <parent link="base_link"/>
    <child link="right_back_motor"/>
    <axis xyz="0 1 0"/>
  </joint>
  <gazebo reference="right_back_motor">
    <material>Gazebo/Yellow</material>
  </gazebo>
  <link name="right_back_motor">
    <visual>
      <origin xyz="0 0 0" rpy="1.5707 0 0"/>
      <geometry>
        <cylinder radius="0.02" length="0.08"/>
      </geometry>
      <material name="yellow">
        <color rgba="0.75 0.75 0.75 1"/>
      </material>
    </visual>
    <inertial>
      <mass value="2"/>
      <origin xyz="0 0 0.0"/>
      <inertia ixx="0.01" ixy="0.0" ixz="0.0" iyy="0.01" iyz="0.0" izz="0.5"/>
    </inertial>
  </link>


  <joint name="right_back_wheel_joint" type="continuous">
    <origin xyz="0 -0.05 0" rpy="0 0 0"/>
    <parent link="right_back_motor"/>
    <child link="right_back_wheel"/>
    <axis xyz="0 1 0"/>
  </joint>
  <gazebo reference="right_back_wheel">
    <material>Gazebo/Black</material>
  </gazebo>
  <link name="right_back_wheel">
    <visual>
      <origin xyz="0 0 0" rpy="1.5707 1.5707 0"/>
      <geometry>
        <cylinder radius="0.04" length="0.04"/>
      </geometry>
      <material name="black">
        <color rgba="0.75 0.75 0.75 1"/>
      </material>
    </visual>
    <inertial>
      <mass value="2"/>
      <origin xyz="0 0 0.0"/>
      <inertia ixx="0.01" ixy="0.0" ixz="0.0" iyy="0.01" iyz="0.0" izz="0.5"/>
    </inertial>
  </link>




  <transmission name="simple_trans">
    <type>transmission_interface/SimpleTransmission</type>
    <joint name="right_back_wheel_joint"/>
    <actuator name="right_back_wheel">
      <hardwareInterface>VelocityJointInterface</hardwareInterface>
      <mechanicalReduction>1</mechanicalReduction>
    </actuator>
  </transmission>
  <transmission name="simple_trans">
    <type>transmission_interface/SimpleTransmission</type>
    <joint name="right_front_wheel_joint"/>
    <actuator name="right_front_wheel">
      <hardwareInterface>VelocityJointInterface</hardwareInterface>
      <mechanicalReduction>1</mechanicalReduction>
    </actuator>
  </transmission>  
  <transmission name="simple_trans">
    <type>transmission_interface/SimpleTransmission</type>
    <joint name="left_back_wheel_joint"/>
    <actuator name="left_back_mwheel">
      <hardwareInterface>VelocityJointInterface</hardwareInterface>
      <mechanicalReduction>1</mechanicalReduction>
    </actuator>
  </transmission>  
  <transmission name="simple_trans">
    <type>transmission_interface/SimpleTransmission</type>
    <joint name="left_front_wheel_joint"/>
    <actuator name="left_front_wheel">
      <hardwareInterface>VelocityJointInterface</hardwareInterface>
      <mechanicalReduction>1</mechanicalReduction>
    </actuator>
  </transmission>
  <gazebo>
    <plugin name="skid_steer_drive_controller" filename="libgazebo_ros_skid_steer_drive.so">
      <rosDebugLevel>Debug</rosDebugLevel>
      <publishWheelTF>true</publishWheelTF>
      <publishTF>1</publishTF>
      <publishWheelJointState>true</publishWheelJointState>
      <updateRate>100.0</updateRate>
      <robotNamespace>/</robotNamespace>
      <leftFrontJoint>right_back_wheel_joint</leftFrontJoint>
      <rightFrontJoint>right_front_wheel_joint</rightFrontJoint>
      <leftRearJoint>left_back_wheel_joint</leftRearJoint>
      <rightRearJoint>left_front_wheel_joint</rightRearJoint>
      <wheelSeparation>0.3</wheelSeparation>
      <wheelDiameter>0.25</wheelDiameter>
      <robotBaseFrame>base_link</robotBaseFrame>
      <torque>20</torque>
      <wheelAcceleration>1.8</wheelAcceleration>
      <topicName>cmd_vel</topicName>
      <broadcastTF>1</broadcastTF>
      <odometryTopic>odom</odometryTopic>
      <odometryFrame>odom</odometryFrame>
    </plugin>
  </gazebo>
</robot>
